Workbook
Name Format: #REF!
Name Header: #REF!
Name RawData: 'ALTA 20242025'!$A$2:$DI$195

Sheet AE GF  (2)
D2: J (Ficha técnica) | E2: P3 (Permiso circulación) | AT2: CALCULOS GLOBAL OMNIUM | BD2: CALCULOS GLOBAL FACTOR
B3: ID CAE | C3: Matricula | D3: TIPO VEHÍCULO | E3: COMBUSTIBLE | F3: Columna4 | G3: Columna5 | H3: Contrato | I3: Acta de Entrega | J3: Acta Devolución | K3: BAJA | L3: Ficha Técnica | M3: Permiso de Circulación | N3: IVTM | O3: Compañía/Proveedor | P3: Cod.Tipo Contrato | Q3: Tipo Contrato | R3: Situación Contrato | S3: f Vig Inicio | T3: F.Vig.Final | U3: Tiempo Prop | V3: Año | W3: Cod.Sit.Contrato | X3: Combustible2 | Y3: Marca | Z3: Modelo/Versión | AA3: Cod.Sociedad | AB3: Sociedad | AC3: Ceco.Imput | AD3: Columna1 | AE3: Matricula nueva | AF3: Marca2 | AG3: Modelo/Versión3 | AH3: Combustible4 | AI3: Ceco | AJ3: Renov. Flota | AK3: Fecha Alta | AL3: Columna3 | AM3: Cod.Sociedad5 | AN3: Pedido | AO3: Sociedad6 | AP3: Ceco imputado | AQ3: Factura | AR3: Comunidad Autonoma | AS3: CHASIS/Bastidor | AT3: CVA | AU3: F | AV3: CVN | AW3: L | AX3: AE | AY3: Columna2 | AZ3: Vacias | BA3: Tipo vehículo2 | BB3: Tipo combustible | BC3: ID CAE2 | BD3: CVA2 | BE3: f2 | BF3: CVN2 | BG3: L2 | BH3: AE [kWh] | BI3: Comprobación | BJ3: Comprobación 2 | BK3: f23 | BL3: CVN22 | BM3: L23
A4: 1 | B4: CAE500001 | C4: 9853KXP | D4: M1 | E4: GASOLINA | F4: GASOLINA | G4: M1 | H4: X | I4: X | J4: X | L4: X | M4: X | O4: AYVENS | P4: 3 | Q4: ALQUILER | R4: DEVUELTO | S4: 45286 | T4: 45322 | U4: 36 | V4: 2024 | W4: 7 | X4: DIESEL | Y4: PEUGEOT | Z4: 208 | AA4: 1021 | AB4: MEDICION AVANZADA CONTAD. | AC4: 357712 | AD4: 1 | AE4: 0696MWT | AF4: RENAULT | AG4: KANGOO VAN E-TECH ELECTRIC | AH4: ELECTRICO | AI4: 357107 | AJ4: 2024 | AK4: 45625 | AL4: 0 | AM4: 1021 | AN4: 4500426762 | AO4: MEDICION AVANZADA CONTAD. | AQ4: X | AR4: COMUNIDAD VALENCIANA | AS4: VF1RFK00273824834 | AT4: 5.1 | AU4: 10 | AV4: 17.3 | AW4: 13073 | AX4: 4405.601 | AY4: M1 | AZ4: CORRECTO ALQUILER | BA4: =+IF(Tabla467824[[#This Row],[TIPO VEHÍCULO]]=Tabla467824[[#This Row],[Columna2]], "IGUAL", "DISTINTO") -> IGUAL | BB4: =+IF(Tabla467824[[#This Row],[Columna4]]=Tabla467824[[#This Row],[Combustible2]], "IGUAL", "DISTINTO") -> DISTINTO | BC4: CAE500001 | BD4: {=IFERROR(INDEX('[1]Anexos FICHA TRA050'!$D$27:$D$44, MATCH(Tabla467824[[#This Row],[Columna5]]&Tabla467824[[#This Row],[Columna4]], '[1]Anexos FICHA TRA050'!$E$27:$E$44&'[1]Anexos FICHA TRA050'!$F$27:$F$44, 0)), "")} -> 7.89 | BE4: =IFERROR(INDEX('[1]Anexos FICHA TRA050'!$B$4:$B$7, MATCH(Tabla467824[[#This Row],[Columna4]], '[1]Anexos FICHA TRA050'!$C$4:$C$7, 0)), "") -> 9.19 | BF4: =IFERROR(INDEX('[1]Anexos FICHA TRA050'!$C$14:$C$22, MATCH(Tabla467824[[#This Row],[Columna5]], '[1]Anexos FICHA TRA050'!$D$14:$D$22, 0)), "") -> 17.92 | BG4: =IFERROR(INDEX('[1]Anexos FICHA TRA050'!$C$49:$C$54, MATCH(Tabla467824[[#This Row],[Columna5]], '[1]Anexos FICHA TRA050'!$D$49:$D$54, 0)), "") -> 13073 | BH4: =+(((Tabla467824[[#This Row],[CVA2]]*Tabla467824[[#This Row],[f2]])-Tabla467824[[#This Row],[CVN2]])/100)*Tabla467824[[#This Row],[L2]] -> 7136.433 | BK4: =+IF(Tabla467824[[#This Row],[F]]=Tabla467824[[#This Row],[f2]], "IGUAL", "DISTINTO") -> DISTINTO | BL4: =+IF(Tabla467824[[#This Row],[CVN]]=Tabla467824[[#This Row],[CVN2]], "IGUAL", "DISTINTO") -> DISTINTO | BM4: =+IF(Tabla467824[[#This Row],[L]]=Tabla467824[[#This Row],[L2]], "IGUAL", "DISTINTO") -> IGUAL
A5: 2 | B5: CAE500002 | C5: 3483KWB | D5: M1 | E5: DIESEL | F5: DIESEL | G5: M1 | H5: X | I5: X | J5: X | L5: X | M5: X | O5: AYVENS | P5: 3 | Q5: ALQUILER | R5: DEVUELTO | S5: 45282 | T5: 45393 | U5: 111 | V5: 2024 | W5: 7 | X5: DIESEL | Y5: PEUGEOT | Z5: 208 | AA5: 1021 | AB5: MEDICION AVANZADA CONTAD. | AC5: 357712 | AD5: 2 | AE5: 0699MWT | AF5: RENAULT | AG5: KANGOO VAN E-TECH ELECTRIC | AH5: ELECTRICO | AI5: 357107 | AJ5: 2024 | AK5: 45625 | AL5: 0 | AM5: 1021 | AN5: 4500426781 | AO5: MEDICION AVANZADA CONTAD. | AQ5: X | AR5: COMUNIDAD VALENCIANA | AS5: VF1RFK00473824835 | AT5: 5.1 | AU5: 10 | AV5: 17.3 | AW5: 13073 | AX5: 4405.601 | AY5: M1 | AZ5: CORRECTO ALQUILER | BA5: =+IF(Tabla467824[[#This Row],[TIPO VEHÍCULO]]=Tabla467824[[#This Row],[Columna2]], "IGUAL", "DISTINTO") -> IGUAL | BB5: =+IF(Tabla467824[[#This Row],[Columna4]]=Tabla467824[[#This Row],[Combustible2]], "IGUAL", "DISTINTO") -> IGUAL | BC5: CAE500002 | BD5: {=IFERROR(INDEX('[1]Anexos FICHA TRA050'!$D$27:$D$44, MATCH(Tabla467824[[#This Row],[Columna5]]&Tabla467824[[#This Row],[Columna4]], '[1]Anexos FICHA TRA050'!$E$27:$E$44&'[1]Anexos FICHA TRA050'!$F$27:$F$44, 0)), "")} -> 6.99 | BE5: =IFERROR(INDEX('[1]Anexos FICHA TRA050'!$B$4:$B$7, MATCH(Tabla467824[[#This Row],[Columna4]], '[1]Anexos FICHA TRA050'!$C$4:$C$7, 0)), "") -> 10 | BF5: =IFERROR(INDEX('[1]Anexos FICHA TRA050'!$C$14:$C$22, MATCH(Tabla467824[[#This Row],[Columna5]], '[1]Anexos FICHA TRA050'!$D$14:$D$22, 0)), "") -> 17.92 | BG5: =IFERROR(INDEX('[1]Anexos FICHA TRA050'!$C$49:$C$54, MATCH(Tabla467824[[#This Row],[Columna5]], '[1]Anexos FICHA TRA050'!$D$49:$D$54, 0)), "") -> 13073 | BH5: =+(((Tabla467824[[#This Row],[CVA2]]*Tabla467824[[#This Row],[f2]])-Tabla467824[[#This Row],[CVN2]])/100)*Tabla467824[[#This Row],[L2]] -> 6795.3454 | BK5: =+IF(Tabla467824[[#This Row],[F]]=Tabla467824[[#This Row],[f2]], "IGUAL", "DISTINTO") -> IGUAL | BL5: =+IF(Tabla467824[[#This Row],[CVN]]=Tabla467824[[#This Row],[CVN2]], "IGUAL", "DISTINTO") -> DISTINTO | BM5: =+IF(Tabla467824[[#This Row],[L]]=Tabla467824[[#This Row],[L2]], "IGUAL", "DISTINTO") -> IGUAL
A6: 3 | B6: CAE500003 | C6: 0041LWY | D6: M1 | E6: DIESEL | F6: DIESEL | G6: M1 | H6: X | J6: X | L6: X | M6: X | O6: AYVENS | P6: 3 | Q6: ALQUILER | R6: DEVUELTO | S6: 45202 | T6: 45259 | U6: 57 | V6: 2023 | W6: 7 | X6: DIESEL | Y6: PEUGEOT | Z6: 208 100 CV | AA6: 1505 | AB6: CGAC | AC6: 355589 | AD6: 1 | AE6: 1255MJM | AF6: PEUGEOT | AG6: E-EXPERT PRO 100 KW | AH6: ELECTRICO | AI6: 725455 | AJ6: 2023 | AK6: 45133 | AL6: 0 | AM6: 1505 | AN6: 4500370218 | AO6: CGAC | AQ6: X | AR6: CATALUÑA | AS6: VF3V1ZKXZPZ005196 | AT6: 5.1 | AU6: 10 | AV6: 28.2 | AW6: 13073 | AX6: 2980.644 | AY6: M1 | AZ6: CORRECTO ALQUILER | BA6: =+IF(Tabla467824[[#This Row],[TIPO VEHÍCULO]]=Tabla467824[[#This Row],[Columna2]], "IGUAL", "DISTINTO") -> IGUAL | BB6: =+IF(Tabla467824[[#This Row],[Columna4]]=Tabla467824[[#This Row],[Combustible2]], "IGUAL", "DISTINTO") -> IGUAL | BC6: CAE500003 | BD6: {=IFERROR(INDEX('[1]Anexos FICHA TRA050'!$D$27:$D$44, MATCH(Tabla467824[[#This Row],[Columna5]]&Tabla467824[[#This Row],[Columna4]], '[1]Anexos FICHA TRA050'!$E$27:$E$44&'[1]Anexos FICHA TRA050'!$F$27:$F$44, 0)), "")} -> 6.99 | BE6: =IFERROR(INDEX('[1]Anexos FICHA TRA050'!$B$4:$B$7, MATCH(Tabla467824[[#This Row],[Columna4]], '[1]Anexos FICHA TRA050'!$C$4:$C$7, 0)), "") -> 10 | BF6: =IFERROR(INDEX('[1]Anexos FICHA TRA050'!$C$14:$C$22, MATCH(Tabla467824[[#This Row],[Columna5]], '[1]Anexos FICHA TRA050'!$D$14:$D$22, 0)), "") -> 17.92 | BG6: =IFERROR(INDEX('[1]Anexos FICHA TRA050'!$C$49:$C$54, MATCH(Tabla467824[[#This Row],[Columna5]], '[1]Anexos FICHA TRA050'!$D$49:$D$54, 0)), "") -> 13073 | BH6: =+(((Tabla467824[[#This Row],[CVA2]]*Tabla467824[[#This Row],[f2]])-Tabla467824[[#This Row],[CVN2]])/100)*Tabla467824[[#This Row],[L2]] -> 6795.3454 | BK6: =+IF(Tabla467824[[#This Row],[F]]=Tabla467824[[#This Row],[f2]], "IGUAL", "DISTINTO") -> IGUAL | BL6: =+IF(Tabla467824[[#This Row],[CVN]]=Tabla467824[[#This Row],[CVN2]], "IGUAL", "DISTINTO") -> DISTINTO | BM6: =+IF(Tabla467824[[#This Row],[L]]=Tabla467824[[#This Row],[L2]], "IGUAL", "DISTINTO") -> IGUAL
A7: 4 | B7: CAE500004 | C7: 5713LWX | D7: M1 | E7: DIESEL | F7: DIESEL | G7: M1 | H7: X | I7: X | J7: X | L7: X | M7: X | O7: AYVENS | P7: 3 | Q7: ALQUILER | R7: DEVUELTO | S7: 45202 | T7: 45261 | U7: 59 | V7: 2023 | W7: 7 | X7: DIESEL | Y7: PEUGEOT | Z7: 208 100 CV | AA7: 1505 | AB7: CGAC | AC7: 355589 | AD7: 2 | AE7: 2120MFK | AF7: RENAULT | AG7: KANGOO VAN E-TECH | AH7: ELECTRICO | AI7: 725465 | AJ7: 2023 | AK7: 44994 | AL7: 0 | AM7: 1505 | AN7: 4500351521 | AO7: CGAC | AQ7: X | AR7: CATALUÑA | AS7: VF1RFK00970687019 | AT7: 5.1 | AU7: 10 | AV7: 17.3 | AW7: 13073 | AX7: 4405.601 | AY7: M1 | AZ7: CORRECTO ALQUILER | BA7: =+IF(Tabla467824[[#This Row],[TIPO VEHÍCULO]]=Tabla467824[[#This Row],[Columna2]], "IGUAL", "DISTINTO") -> IGUAL | BB7: =+IF(Tabla467824[[#This Row],[Columna4]]=Tabla467824[[#This Row],[Combustible2]], "IGUAL", "DISTINTO") -> IGUAL | BC7: CAE500004 | BD7: {=IFERROR(INDEX('[1]Anexos FICHA TRA050'!$D$27:$D$44, MATCH(Tabla467824[[#This Row],[Columna5]]&Tabla467824[[#This Row],[Columna4]], '[1]Anexos FICHA TRA050'!$E$27:$E$44&'[1]Anexos FICHA TRA050'!$F$27:$F$44, 0)), "")} -> 6.99 | BE7: =IFERROR(INDEX('[1]Anexos FICHA TRA050'!$B$4:$B$7, MATCH(Tabla467824[[#This Row],[Columna4]], '[1]Anexos FICHA TRA050'!$C$4:$C$7, 0)), "") -> 10 | BF7: =IFERROR(INDEX('[1]Anexos FICHA TRA050'!$C$14:$C$22, MATCH(Tabla467824[[#This Row],[Columna5]], '[1]Anexos FICHA TRA050'!$D$14:$D$22, 0)), "") -> 17.92 | BG7: =IFERROR(INDEX('[1]Anexos FICHA TRA050'!$C$49:$C$54, MATCH(Tabla467824[[#This Row],[Columna5]], '[1]Anexos FICHA TRA050'!$D$49:$D$54, 0)), "") -> 13073 | BH7: =+(((Tabla467824[[#This Row],[CVA2]]*Tabla467824[[#This Row],[f2]])-Tabla467824[[#This Row],[CVN2]])/100)*Tabla467824[[#This Row],[L2]] -> 6795.3454 | BK7: =+IF(Tabla467824[[#This Row],[F]]=Tabla467824[[#This Row],[f2]], "IGUAL", "DISTINTO") -> IGUAL | BL7: =+IF(Tabla467824[[#This Row],[CVN]]=Tabla467824[[#This Row],[CVN2]], "IGUAL", "DISTINTO") -> DISTINTO | BM7: =+IF(Tabla467824[[#This Row],[L]]=Tabla467824[[#This Row],[L2]], "IGUAL", "DISTINTO") -> IGUAL
A8: 5 | B8: CAE500005 | C8: 5056LWD | D8: M1 | E8: DIESEL | F8: DIESEL | G8: M1 | H8: X | J8: X | L8: X | M8: X | O8: AYVENS | P8: 3 | Q8: ALQUILER | R8: DEVUELTO | S8: 45397 | T8: 45414 | U8: 17 | V8: 2024 | W8: 7 | X8: DIESEL | Y8: PEUGEOT | Z8: 208 100 CV | AA8: 1001 | AB8: AVSA | AC8: 201347 | AD8: 1 | AE8: 2788MXG | AF8: RENAULT | AG8: KANGOO VAN E-TECH ELECTRIC | AH8: ELECTRICO | AI8: 201420 | AJ8: 2024 | AK8: 45645 | AL8: 0 | AM8: 1001 | AN8: 4500426876 | AO8: AVSA | AQ8: X | AR8: COMUNIDAD VALENCIANA | AS8: VF1RFK00273934296 | AT8: 5.1 | AU8: 10 | AV8: 17.3 | AW8: 13073 | AX8: 4405.601 | AY8: M1 | AZ8: CORRECTO ALQUILER | BA8: =+IF(Tabla467824[[#This Row],[TIPO VEHÍCULO]]=Tabla467824[[#This Row],[Columna2]], "IGUAL", "DISTINTO") -> IGUAL | BB8: =+IF(Tabla467824[[#This Row],[Columna4]]=Tabla467824[[#This Row],[Combustible2]], "IGUAL", "DISTINTO") -> IGUAL | BC8: CAE500005 | BD8: {=IFERROR(INDEX('[1]Anexos FICHA TRA050'!$D$27:$D$44, MATCH(Tabla467824[[#This Row],[Columna5]]&Tabla467824[[#This Row],[Columna4]], '[1]Anexos FICHA TRA050'!$E$27:$E$44&'[1]Anexos FICHA TRA050'!$F$27:$F$44, 0)), "")} -> 6.99 | BE8: =IFERROR(INDEX('[1]Anexos FICHA TRA050'!$B$4:$B$7, MATCH(Tabla467824[[#This Row],[Columna4]], '[1]Anexos FICHA TRA050'!$C$4:$C$7, 0)), "") -> 10 | BF8: =IFERROR(INDEX('[1]Anexos FICHA TRA050'!$C$14:$C$22, MATCH(Tabla467824[[#This Row],[Columna5]], '[1]Anexos FICHA TRA050'!$D$14:$D$22, 0)), "") -> 17.92 | BG8: =IFERROR(INDEX('[1]Anexos FICHA TRA050'!$C$49:$C$54, MATCH(Tabla467824[[#This Row],[Columna5]], '[1]Anexos FICHA TRA050'!$D$49:$D$54, 0)), "") -> 13073 | BH8: =+(((Tabla467824[[#This Row],[CVA2]]*Tabla467824[[#This Row],[f2]])-Tabla467824[[#This Row],[CVN2]])/100)*Tabla467824[[#This Row],[L2]] -> 6795.3454 | BK8: =+IF(Tabla467824[[#This Row],[F]]=Tabla467824[[#This Row],[f2]], "IGUAL", "DISTINTO") -> IGUAL | BL8: =+IF(Tabla467824[[#This Row],[CVN]]=Tabla467824[[#This Row],[CVN2]], "IGUAL", "DISTINTO") -> DISTINTO | BM8: =+IF(Tabla467824[[#This Row],[L]]=Tabla467824[[#This Row],[L2]], "IGUAL", "DISTINTO") -> IGUAL
A9: 6 | B9: CAE500006 | C9: 0370LXS | D9: N1 | E9: DIESEL | F9: DIESEL | G9: N1 | H9: X | J9: X | L9: X | M9: X | O9: TLM | P9: 3 | Q9: ALQUILER | R9: DEVUELTO | S9: 45447 | T9: 45657 | U9: 210 | V9: 2024 | W9: 7 | X9: DIESEL | Y9: PEUGEOT | Z9: BOXER L2 H2 140 CV | AA9: 1066 | AB9: CANALIZ. CIVILES S.A. | AC9: 10669101 | AD9: 1 | AE9: 8651MWT | AF9: RENAULT | AG9: KANGOO VAN E-TECH ELECTRIC | AH9: ELECTRICO | AI9: 10669120 | AJ9: 2024 | AK9: 45625 | AL9: 0 | AM9: 1066 | AN9: 4500426872 | AO9: CANALIZ. CIVILES S.A. | AQ9: X | AR9: COMUNIDAD VALENCIANA | AS9: VF1RFK00073824833 | AT9: 5.6 | AU9: 10 | AV9: 17.3 | AW9: 15815 | AX9: 6120.405 | AY9: N1 | AZ9: CORRECTO ALQUILER | BA9: =+IF(Tabla467824[[#This Row],[TIPO VEHÍCULO]]=Tabla467824[[#This Row],[Columna2]], "IGUAL", "DISTINTO") -> IGUAL | BB9: =+IF(Tabla467824[[#This Row],[Columna4]]=Tabla467824[[#This Row],[Combustible2]], "IGUAL", "DISTINTO") -> IGUAL | BC9: CAE500006 | BD9: {=IFERROR(INDEX('[1]Anexos FICHA TRA050'!$D$27:$D$44, MATCH(Tabla467824[[#This Row],[Columna5]]&Tabla467824[[#This Row],[Columna4]], '[1]Anexos FICHA TRA050'!$E$27:$E$44&'[1]Anexos FICHA TRA050'!$F$27:$F$44, 0)), "")} -> 5.63 | BE9: =IFERROR(INDEX('[1]Anexos FICHA TRA050'!$B$4:$B$7, MATCH(Tabla467824[[#This Row],[Columna4]], '[1]Anexos FICHA TRA050'!$C$4:$C$7, 0)), "") -> 10 | BF9: =IFERROR(INDEX('[1]Anexos FICHA TRA050'!$C$14:$C$22, MATCH(Tabla467824[[#This Row],[Columna5]], '[1]Anexos FICHA TRA050'!$D$14:$D$22, 0)), "") -> 20.84 | BG9: =IFERROR(INDEX('[1]Anexos FICHA TRA050'!$C$49:$C$54, MATCH(Tabla467824[[#This Row],[Columna5]], '[1]Anexos FICHA TRA050'!$D$49:$D$54, 0)), "") -> 15815 | BH9: =+(((Tabla467824[[#This Row],[CVA2]]*Tabla467824[[#This Row],[f2]])-Tabla467824[[#This Row],[CVN2]])/100)*Tabla467824[[#This Row],[L2]] -> 5607.999 | BK9: =+IF(Tabla467824[[#This Row],[F]]=Tabla467824[[#This Row],[f2]], "IGUAL", "DISTINTO") -> IGUAL | BL9: =+IF(Tabla467824[[#This Row],[CVN]]=Tabla467824[[#This Row],[CVN2]], "IGUAL", "DISTINTO") -> DISTINTO | BM9: =+IF(Tabla467824[[#This Row],[L]]=Tabla467824[[#This Row],[L2]], "IGUAL", "DISTINTO") -> IGUAL
A10: 7 | B10: CAE500007 | C10: 1865LDL | D10: M1 | E10: DIESEL | F10: DIESEL | G10: M1 | H10: X | I10: X | J10: X | L10: X | M10: X | O10: AYVENS | P10: 3 | Q10: ALQUILER | R10: DEVUELTO | S10: 45282 | T10: 45321 | U10: 39 | V10: 2024 | W10: 7 | X10: DIESEL | Y10: CITROEN | Z10: C3 | AA10: 1021 | AB10: MEDICION AVANZADA CONTAD. | AC10: 357712 | AD10: 3 | AE10: 0695MWT | AF10: RENAULT | AG10: KANGOO VAN E-TECH ELECTRIC | AH10: ELECTRICO | AI10: 357706 | AJ10: 2024 | AK10: 45625 | AL10: 0 | AM10: 1021 | AN10: 4500426841 | AO10: MEDICION AVANZADA CONTAD. | AQ10: X | AR10: COMUNIDAD VALENCIANA | AS10: VF1RFK00773824845 | AT10: 5.1 | AU10: 10 | AV10: 17.3 | AW10: 13073 | AX10: 4405.601 | AY10: M1 | AZ10: CORRECTO ALQUILER | BA10: =+IF(Tabla467824[[#This Row],[TIPO VEHÍCULO]]=Tabla467824[[#This Row],[Columna2]], "IGUAL", "DISTINTO") -> IGUAL | BB10: =+IF(Tabla467824[[#This Row],[Columna4]]=Tabla467824[[#This Row],[Combustible2]], "IGUAL", "DISTINTO") -> IGUAL | BC10: CAE500007 | BD10: {=IFERROR(INDEX('[1]Anexos FICHA TRA050'!$D$27:$D$44, MATCH(Tabla467824[[#This Row],[Columna5]]&Tabla467824[[#This Row],[Columna4]], '[1]Anexos FICHA TRA050'!$E$27:$E$44&'[1]Anexos FICHA TRA050'!$F$27:$F$44, 0)), "")} -> 6.99 | BE10: =IFERROR(INDEX('[1]Anexos FICHA TRA050'!$B$4:$B$7, MATCH(Tabla467824[[#This Row],[Columna4]], '[1]Anexos FICHA TRA050'!$C$4:$C$7, 0)), "") -> 10 | BF10: =IFERROR(INDEX('[1]Anexos FICHA TRA050'!$C$14:$C$22, MATCH(Tabla467824[[#This Row],[Columna5]], '[1]Anexos FICHA TRA050'!$D$14:$D$22, 0)), "") -> 17.92 | BG10: =IFERROR(INDEX('[1]Anexos FICHA TRA050'!$C$49:$C$54, MATCH(Tabla467824[[#This Row],[Columna5]], '[1]Anexos FICHA TRA050'!$D$49:$D$54, 0)), "") -> 13073 | BH10: =+(((Tabla467824[[#This Row],[CVA2]]*Tabla467824[[#This Row],[f2]])-Tabla467824[[#This Row],[CVN2]])/100)*Tabla467824[[#This Row],[L2]] -> 6795.3454 | BK10: =+IF(Tabla467824[[#This Row],[F]]=Tabla467824[[#This Row],[f2]], "IGUAL", "DISTINTO") -> IGUAL | BL10: =+IF(Tabla467824[[#This Row],[CVN]]=Tabla467824[[#This Row],[CVN2]], "IGUAL", "DISTINTO") -> DISTINTO | BM10: =+IF(Tabla467824[[#This Row],[L]]=Tabla467824[[#This Row],[L2]], "IGUAL", "DISTINTO") -> IGUAL
A11: 8 | B11: CAE500008 | C11: 4295MRH | D11: M1 | E11: DIESEL | F11: DIESEL | G11: M1 | H11: X | J11: X | L11: X | M11: X | O11: AYVENS | P11: 3 | Q11: ALQUILER | R11: DEVUELTO | S11: 45451 | T11: 45565 | U11: 114 | V11: 2024 | W11: 7 | X11: DIESEL | Y11: CITROEN | Z11: C3 100 CV | AA11: 1001 | AB11: AVSA | AC11: 101353 | AD11: 2 | AE11: 6015MWV | AF11: CITROEN | AG11: Ë-C3 ELÉCTRICO MAX | AH11: ELECTRICO | AI11: 200567 | AJ11: 2024 | AK11: 45622 | AL11: 0 | AM11: 1001 | AN11: 4500424209 | AO11: AVSA | AQ11: X | AR11: COMUNIDAD VALENCIANA | AS11: VR7CBZYAXRT152191 | AT11: 5.1 | AU11: 10 | AV11: 16.4 | AW11: 13073 | AX11: 4523.258 | AY11: M1 | AZ11: CORRECTO ALQUILER | BA11: =+IF(Tabla467824[[#This Row],[TIPO VEHÍCULO]]=Tabla467824[[#This Row],[Columna2]], "IGUAL", "DISTINTO") -> IGUAL | BB11: =+IF(Tabla467824[[#This Row],[Columna4]]=Tabla467824[[#This Row],[Combustible2]], "IGUAL", "DISTINTO") -> IGUAL | BC11: CAE500008 | BD11: {=IFERROR(INDEX('[1]Anexos FICHA TRA050'!$D$27:$D$44, MATCH(Tabla467824[[#This Row],[Columna5]]&Tabla467824[[#This Row],[Columna4]], '[1]Anexos FICHA TRA050'!$E$27:$E$44&'[1]Anexos FICHA TRA050'!$F$27:$F$44, 0)), "")} -> 6.99 | BE11: =IFERROR(INDEX('[1]Anexos FICHA TRA050'!$B$4:$B$7, MATCH(Tabla467824[[#This Row],[Columna4]], '[1]Anexos FICHA TRA050'!$C$4:$C$7, 0)), "") -> 10 | BF11: =IFERROR(INDEX('[1]Anexos FICHA TRA050'!$C$14:$C$22, MATCH(Tabla467824[[#This Row],[Columna5]], '[1]Anexos FICHA TRA050'!$D$14:$D$22, 0)), "") -> 17.92 | BG11: =IFERROR(INDEX('[1]Anexos FICHA TRA050'!$C$49:$C$54, MATCH(Tabla467824[[#This Row],[Columna5]], '[1]Anexos FICHA TRA050'!$D$49:$D$54, 0)), "") -> 13073 | BH11: =+(((Tabla467824[[#This Row],[CVA2]]*Tabla467824[[#This Row],[f2]])-Tabla467824[[#This Row],[CVN2]])/100)*Tabla467824[[#This Row],[L2]] -> 6795.3454 | BK11: =+IF(Tabla467824[[#This Row],[F]]=Tabla467824[[#This Row],[f2]], "IGUAL", "DISTINTO") -> IGUAL | BL11: =+IF(Tabla467824[[#This Row],[CVN]]=Tabla467824[[#This Row],[CVN2]], "IGUAL", "DISTINTO") -> DISTINTO | BM11: =+IF(Tabla467824[[#This Row],[L]]=Tabla467824[[#This Row],[L2]], "IGUAL", "DISTINTO") -> IGUAL
A12: 9 | B12: CAE500010 | C12: 8213KFW | D12: L3e | E12: GASOLINA | F12: GASOLINA | G12: L | H12: X | K12: X | L12: X | M12: X | O12: PROPIEDAD | P12: 5 | Q12: PROPIEDAD | R12: CANCELADO POR SINIESTRO | S12: 43073 | T12: 44974 | U12: 1901 | V12: 2023 | W12: 6 | X12: GASOLINA | Y12: KYMCO | Z12: AGILITY CITY 125 CC | AA12: 1021 | AB12: MEDICION AVANZADA CONTAD. | AC12: 357108 | AD12: 4 | AE12: 0692MWT | AF12: RENAULT | AG12: KANGOO VAN E-TECH ELECTRIC | AH12: ELECTRICO | AI12: 357706 | AJ12: 2024 | AK12: 45625 | AL12: 1 | AM12: 1021 | AN12: 4500426794 | AO12: MEDICION AVANZADA CONTAD. | AQ12: X | AR12: COMUNIDAD VALENCIANA | AS12: VF1RFK00173824842 | AT12: 2.9 | AU12: 9.19 | AV12: 17.3 | AW12: 2831 | AX12: 264.72681 | AY12: L3e | AZ12: CORRECTO PROPIEDAD | BA12: =+IF(Tabla467824[[#This Row],[TIPO VEHÍCULO]]=Tabla467824[[#This Row],[Columna2]], "IGUAL", "DISTINTO") -> IGUAL | BB12: =+IF(Tabla467824[[#This Row],[Columna4]]=Tabla467824[[#This Row],[Combustible2]], "IGUAL", "DISTINTO") -> IGUAL | BC12: CAE500010 | BD12: {=IFERROR(INDEX('[1]Anexos FICHA TRA050'!$D$27:$D$44, MATCH(Tabla467824[[#This Row],[Columna5]]&Tabla467824[[#This Row],[Columna4]], '[1]Anexos FICHA TRA050'!$E$27:$E$44&'[1]Anexos FICHA TRA050'!$F$27:$F$44, 0)), "")} -> 2.9 | BE12: =IFERROR(INDEX('[1]Anexos FICHA TRA050'!$B$4:$B$7, MATCH(Tabla467824[[#This Row],[Columna4]], '[1]Anexos FICHA TRA050'!$C$4:$C$7, 0)), "") -> 9.19 | BF12: =IFERROR(INDEX('[1]Anexos FICHA TRA050'!$C$14:$C$22, MATCH(Tabla467824[[#This Row],[Columna5]], '[1]Anexos FICHA TRA050'!$D$14:$D$22, 0)), "") -> 4.84 | BG12: =IFERROR(INDEX('[1]Anexos FICHA TRA050'!$C$49:$C$54, MATCH(Tabla467824[[#This Row],[Columna5]], '[1]Anexos FICHA TRA050'!$D$49:$D$54, 0)), "") -> 2831 | BH12: =+(((Tabla467824[[#This Row],[CVA2]]*Tabla467824[[#This Row],[f2]])-Tabla467824[[#This Row],[CVN2]])/100)*Tabla467824[[#This Row],[L2]] -> 617.46941 | BK12: =+IF(Tabla467824[[#This Row],[F]]=Tabla467824[[#This Row],[f2]], "IGUAL", "DISTINTO") -> IGUAL | BL12: =+IF(Tabla467824[[#This Row],[CVN]]=Tabla467824[[#This Row],[CVN2]], "IGUAL", "DISTINTO") -> DISTINTO | BM12: =+IF(Tabla467824[[#This Row],[L]]=Tabla467824[[#This Row],[L2]], "IGUAL", "DISTINTO") -> IGUAL
A13: 10 | B13: CAE500011 | C13: 0909HZB | D13: L3e | E13: GASOLINA | F13: GASOLINA | G13: L | H13: X | K13: X | L13: X | M13: X | O13: PROPIEDAD | P13: 5 | Q13: PROPIEDAD | R13: CANCELADO | S13: 42641 | T13: 45561 | U13: 2920 | V13: 2024 | W13: 4 | X13: GASOLINA | Y13: KYMCO | Z13: AGILITY CITY 125 CC | AA13: 1021 | AB13: MEDICION AVANZADA CONTAD. | AC13: 357108 | AD13: 5 | AE13: 0773MXH | AF13: RENAULT | AG13: KANGOO VAN E-TECH ELECTRIC | AH13: ELECTRICO | AI13: 357708 | AJ13: 2024 | AK13: 45646 | AL13: 0 | AM13: 1021 | AN13: 4500426849 | AO13: MEDICION AVANZADA CONTAD. | AQ13: X | AR13: COMUNIDAD VALENCIANA | AS13: VF1RFK00473824852 | AT13: 2.9 | AU13: 9.19 | AV13: 17.3 | AW13: 2831 | AX13: 264.72681 | AY13: L3e | AZ13: CORRECTO PROPIEDAD | BA13: =+IF(Tabla467824[[#This Row],[TIPO VEHÍCULO]]=Tabla467824[[#This Row],[Columna2]], "IGUAL", "DISTINTO") -> IGUAL | BB13: =+IF(Tabla467824[[#This Row],[Columna4]]=Tabla467824[[#This Row],[Combustible2]], "IGUAL", "DISTINTO") -> IGUAL | BC13: CAE500011 | BD13: {=IFERROR(INDEX('[1]Anexos FICHA TRA050'!$D$27:$D$44, MATCH(Tabla467824[[#This Row],[Columna5]]&Tabla467824[[#This Row],[Columna4]], '[1]Anexos FICHA TRA050'!$E$27:$E$44&'[1]Anexos FICHA TRA050'!$F$27:$F$44, 0)), "")} -> 2.9 | BE13: =IFERROR(INDEX('[1]Anexos FICHA TRA050'!$B$4:$B$7, MATCH(Tabla467824[[#This Row],[Columna4]], '[1]Anexos FICHA TRA050'!$C$4:$C$7, 0)), "") -> 9.19 | BF13: =IFERROR(INDEX('[1]Anexos FICHA TRA050'!$C$14:$C$22, MATCH(Tabla467824[[#This Row],[Columna5]], '[1]Anexos FICHA TRA050'!$D$14:$D$22, 0)), "") -> 4.84 | BG13: =IFERROR(INDEX('[1]Anexos FICHA TRA050'!$C$49:$C$54, MATCH(Tabla467824[[#This Row],[Columna5]], '[1]Anexos FICHA TRA050'!$D$49:$D$54, 0)), "") -> 2831 | BH13: =+(((Tabla467824[[#This Row],[CVA2]]*Tabla467824[[#This Row],[f2]])-Tabla467824[[#This Row],[CVN2]])/100)*Tabla467824[[#This Row],[L2]] -> 617.46941 | BK13: =+IF(Tabla467824[[#This Row],[F]]=Tabla467824[[#This Row],[f2]], "IGUAL", "DISTINTO") -> IGUAL | BL13: =+IF(Tabla467824[[#This Row],[CVN]]=Tabla467824[[#This Row],[CVN2]], "IGUAL", "DISTINTO") -> DISTINTO | BM13: =+IF(Tabla467824[[#This Row],[L]]=Tabla467824[[#This Row],[L2]], "IGUAL", "DISTINTO") -> IGUAL
A14: 11 | B14: CAE500012 | C14: 1987HGR | D14: L3e | E14: GASOLINA | F14: GASOLINA | G14: L | H14: X | K14: X | L14: X | M14: X | O14: PROPIEDAD | P14: 5 | Q14: PROPIEDAD | R14: CANCELADO | S14: 40830 | T14: 45561 | U14: 4731 | V14: 2024 | W14: 4 | X14: GASOLINA | Y14: KYMCO | Z14: AGILITY CITY 125 CC | AA14: 1021 | AB14: MEDICION AVANZADA CONTAD. | AC14: 357108 | AD14: 6 | AE14: 0823MXH | AF14: RENAULT | AG14: KANGOO VAN E-TECH ELECTRIC | AH14: ELECTRICO | AI14: 357752 | AJ14: 2024 | AK14: 45646 | AL14: 0 | AM14: 1021 | AN14: 4500426870 | AO14: MEDICION AVANZADA CONTAD. | AQ14: X | AR14: COMUNIDAD VALENCIANA | AS14: VF1RFK00873824854 | AT14: 2.9 | AU14: 9.19 | AV14: 17.3 | AW14: 2831 | AX14: 264.72681 | AY14: L3e | AZ14: CORRECTO PROPIEDAD | BA14: =+IF(Tabla467824[[#This Row],[TIPO VEHÍCULO]]=Tabla467824[[#This Row],[Columna2]], "IGUAL", "DISTINTO") -> IGUAL | BB14: =+IF(Tabla467824[[#This Row],[Columna4]]=Tabla467824[[#This Row],[Combustible2]], "IGUAL", "DISTINTO") -> IGUAL | BC14: CAE500012 | BD14: {=IFERROR(INDEX('[1]Anexos FICHA TRA050'!$D$27:$D$44, MATCH(Tabla467824[[#This Row],[Columna5]]&Tabla467824[[#This Row],[Columna4]], '[1]Anexos FICHA TRA050'!$E$27:$E$44&'[1]Anexos FICHA TRA050'!$F$27:$F$44, 0)), "")} -> 2.9 | BE14: =IFERROR(INDEX('[1]Anexos FICHA TRA050'!$B$4:$B$7, MATCH(Tabla467824[[#This Row],[Columna4]], '[1]Anexos FICHA TRA050'!$C$4:$C$7, 0)), "") -> 9.19 | BF14: =IFERROR(INDEX('[1]Anexos FICHA TRA050'!$C$14:$C$22, MATCH(Tabla467824[[#This Row],[Columna5]], '[1]Anexos FICHA TRA050'!$D$14:$D$22, 0)), "") -> 4.84 | BG14: =IFERROR(INDEX('[1]Anexos FICHA TRA050'!$C$49:$C$54, MATCH(Tabla467824[[#This Row],[Columna5]], '[1]Anexos FICHA TRA050'!$D$49:$D$54, 0)), "") -> 2831 | BH14: =+(((Tabla467824[[#This Row],[CVA2]]*Tabla467824[[#This Row],[f2]])-Tabla467824[[#This Row],[CVN2]])/100)*Tabla467824[[#This Row],[L2]] -> 617.46941 | BK14: =+IF(Tabla467824[[#This Row],[F]]=Tabla467824[[#This Row],[f2]], "IGUAL", "DISTINTO") -> IGUAL | BL14: =+IF(Tabla467824[[#This Row],[CVN]]=Tabla467824[[#This Row],[CVN2]], "IGUAL", "DISTINTO") -> DISTINTO | BM14: =+IF(Tabla467824[[#This Row],[L]]=Tabla467824[[#This Row],[L2]], "IGUAL", "DISTINTO") -> IGUAL
A15: 12 | B15: CAE500013 | C15: 8449HKF | D15: L3e | E15: GASOLINA | F15: GASOLINA | G15: L | K15: X | L15: X | M15: X | N15: X | O15: PROPIEDAD | P15: 5 | Q15: PROPIEDAD | R15: CANCELADO | S15: 41017 | T15: 45561 | U15: 4544 | V15: 2024 | W15: 4 | X15: GASOLINA | Y15: KYMCO | Z15: AGILITY CITY 125 CC | AA15: 1021 | AB15: MEDICION AVANZADA CONTAD. | AC15: 357108 | AD15: 7 | AE15: 0971MXH | AF15: RENAULT | AG15: KANGOO VAN E-TECH ELECTRIC | AH15: ELECTRICO | AI15: 357708 | AJ15: 2024 | AK15: 45646 | AL15: 0 | AM15: 1021 | AN15: 4500426847 | AO15: MEDICION AVANZADA CONTAD. | AQ15: X | AR15: COMUNIDAD VALENCIANA | AS15: VF1RFK00073824847 | AT15: 2.9 | AU15: 9.19 | AV15: 17.3 | AW15: 2831 | AX15: 264.72681 | AY15: L3e | AZ15: CORRECTO PROPIEDAD | BA15: =+IF(Tabla467824[[#This Row],[TIPO VEHÍCULO]]=Tabla467824[[#This Row],[Columna2]], "IGUAL", "DISTINTO") -> IGUAL | BB15: =+IF(Tabla467824[[#This Row],[Columna4]]=Tabla467824[[#This Row],[Combustible2]], "IGUAL", "DISTINTO") -> IGUAL | BC15: CAE500013 | BD15: {=IFERROR(INDEX('[1]Anexos FICHA TRA050'!$D$27:$D$44, MATCH(Tabla467824[[#This Row],[Columna5]]&Tabla467824[[#This Row],[Columna4]], '[1]Anexos FICHA TRA050'!$E$27:$E$44&'[1]Anexos FICHA TRA050'!$F$27:$F$44, 0)), "")} -> 2.9 | BE15: =IFERROR(INDEX('[1]Anexos FICHA TRA050'!$B$4:$B$7, MATCH(Tabla467824[[#This Row],[Columna4]], '[1]Anexos FICHA TRA050'!$C$4:$C$7, 0)), "") -> 9.19 | BF15: =IFERROR(INDEX('[1]Anexos FICHA TRA050'!$C$14:$C$22, MATCH(Tabla467824[[#This Row],[Columna5]], '[1]Anexos FICHA TRA050'!$D$14:$D$22, 0)), "") -> 4.84 | BG15: =IFERROR(INDEX('[1]Anexos FICHA TRA050'!$C$49:$C$54, MATCH(Tabla467824[[#This Row],[Columna5]], '[1]Anexos FICHA TRA050'!$D$49:$D$54, 0)), "") -> 2831 | BH15: =+(((Tabla467824[[#This Row],[CVA2]]*Tabla467824[[#This Row],[f2]])-Tabla467824[[#This Row],[CVN2]])/100)*Tabla467824[[#This Row],[L2]] -> 617.46941 | BK15: =+IF(Tabla467824[[#This Row],[F]]=Tabla467824[[#This Row],[f2]], "IGUAL", "DISTINTO") -> IGUAL | BL15: =+IF(Tabla467824[[#This Row],[CVN]]=Tabla467824[[#This Row],[CVN2]], "IGUAL", "DISTINTO") -> DISTINTO | BM15: =+IF(Tabla467824[[#This Row],[L]]=Tabla467824[[#This Row],[L2]], "IGUAL", "DISTINTO") -> IGUAL
A16: 13 | B16: CAE500014 | C16: 4579KCW | D16: L3e | E16: GASOLINA | F16: GASOLINA | G16: L | H16: X | K16: X | L16: X | M16: X | O16: PROPIEDAD | P16: 5 | Q16: PROPIEDAD | R16: CANCELADO | S16: 42983 | T16: 45604 | U16: 2621 | V16: 2024 | W16: 4 | X16: GASOLINA | Y16: KYMCO | Z16: AGILITY CITY 125 CC | AA16: 1053 | AB16: ISG | AC16: 355521 | AD16: 1 | AE16: 8349MXG | AF16: RENAULT | AG16: KANGOO VAN E-TECH ELECTRIC | AH16: ELECTRICO | AI16: 355528 | AJ16: 2024 | AK16: 45646 | AL16: 0 | AM16: 1053 | AN16: 4500426779 | AO16: ISG | AQ16: X | AR16: COMUNIDAD VALENCIANA | AS16: VF1RFK00373934291 | AT16: 2.9 | AU16: 9.19 | AV16: 17.3 | AW16: 2831 | AX16: 264.72681 | AY16: L3e | AZ16: CORRECTO PROPIEDAD | BA16: =+IF(Tabla467824[[#This Row],[TIPO VEHÍCULO]]=Tabla467824[[#This Row],[Columna2]], "IGUAL", "DISTINTO") -> IGUAL | BB16: =+IF(Tabla467824[[#This Row],[Columna4]]=Tabla467824[[#This Row],[Combustible2]], "IGUAL", "DISTINTO") -> IGUAL | BC16: CAE500014 | BD16: {=IFERROR(INDEX('[1]Anexos FICHA TRA050'!$D$27:$D$44, MATCH(Tabla467824[[#This Row],[Columna5]]&Tabla467824[[#This Row],[Columna4]], '[1]Anexos FICHA TRA050'!$E$27:$E$44&'[1]Anexos FICHA TRA050'!$F$27:$F$44, 0)), "")} -> 2.9 | BE16: =IFERROR(INDEX('[1]Anexos FICHA TRA050'!$B$4:$B$7, MATCH(Tabla467824[[#This Row],[Columna4]], '[1]Anexos FICHA TRA050'!$C$4:$C$7, 0)), "") -> 9.19 | BF16: =IFERROR(INDEX('[1]Anexos FICHA TRA050'!$C$14:$C$22, MATCH(Tabla467824[[#This Row],[Columna5]], '[1]Anexos FICHA TRA050'!$D$14:$D$22, 0)), "") -> 4.84 | BG16: =IFERROR(INDEX('[1]Anexos FICHA TRA050'!$C$49:$C$54, MATCH(Tabla467824[[#This Row],[Columna5]], '[1]Anexos FICHA TRA050'!$D$49:$D$54, 0)), "") -> 2831 | BH16: =+(((Tabla467824[[#This Row],[CVA2]]*Tabla467824[[#This Row],[f2]])-Tabla467824[[#This Row],[CVN2]])/100)*Tabla467824[[#This Row],[L2]] -> 617.46941 | BK16: =+IF(Tabla467824[[#This Row],[F]]=Tabla467824[[#This Row],[f2]], "IGUAL", "DISTINTO") -> IGUAL | BL16: =+IF(Tabla467824[[#This Row],[CVN]]=Tabla467824[[#This Row],[CVN2]], "IGUAL", "DISTINTO") -> DISTINTO | BM16: =+IF(Tabla467824[[#This Row],[L]]=Tabla467824[[#This Row],[L2]], "IGUAL", "DISTINTO") -> IGUAL
A17: 14 | B17: CAE500015 | C17: 1485LSB | D17: M1 | E17: GASOLINA - Híbridos (HEV) | F17: GASOLINA - Híbridos (HEV) | G17: M1 | H17: X | I17: X | J17: X | L17: X | M17: X | O17: AYVENS | P17: 1 | Q17: RENTING | R17: DEVUELTO | S17: 44414 | T17: 45875 | U17: 1461 | V17: 2025 | W17: 7 | X17: HÍBRIDO | Y17: RENAULT | Z17: ARKANA TCE 140 CV | AA17: 1200 | AB17: EMIVASA | AC17: 12009006 | AD17: 1 | AE17: 3143MWZ | AF17: CITROEN | AG17: Ë-C3 ELÉCTRICO MAX | AH17: ELECTRICO | AI17: 100011 | AJ17: 2024 | AK17: 45638 | AL17: -1 | AM17: 1200 | AN17: 4500424885 | AO17: EMIVASA | AQ17: X | AR17: COMUNIDAD VALENCIANA | AS17: VR7CBZYA5RT154432 | AT17: 5.1 | AU17: 9.19 | AV17: 16.4 | AW17: 13073 | AX17: 3983.2124 | AY17: M1 | AZ17: CORRECTO ALQUILER | BA17: =+IF(Tabla467824[[#This Row],[TIPO VEHÍCULO]]=Tabla467824[[#This Row],[Columna2]], "IGUAL", "DISTINTO") -> IGUAL | BB17: =+IF(Tabla467824[[#This Row],[Columna4]]=Tabla467824[[#This Row],[Combustible2]], "IGUAL", "DISTINTO") -> DISTINTO | BC17: CAE500015 | BD17: {=IFERROR(INDEX('[1]Anexos FICHA TRA050'!$D$27:$D$44, MATCH(Tabla467824[[#This Row],[Columna5]]&Tabla467824[[#This Row],[Columna4]], '[1]Anexos FICHA TRA050'!$E$27:$E$44&'[1]Anexos FICHA TRA050'!$F$27:$F$44, 0)), "")} -> 5.135 | BE17: =+'[1]Anexos FICHA TRA050'!B5 -> 9.19 | BF17: =IFERROR(INDEX('[1]Anexos FICHA TRA050'!$C$14:$C$22, MATCH(Tabla467824[[#This Row],[Columna5]], '[1]Anexos FICHA TRA050'!$D$14:$D$22, 0)), "") -> 17.92 | BG17: =IFERROR(INDEX('[1]Anexos FICHA TRA050'!$C$49:$C$54, MATCH(Tabla467824[[#This Row],[Columna5]], '[1]Anexos FICHA TRA050'!$D$49:$D$54, 0)), "") -> 13073 | BH17: =+(((Tabla467824[[#This Row],[CVA2]]*Tabla467824[[#This Row],[f2]])-Tabla467824[[#This Row],[CVN2]])/100)*Tabla467824[[#This Row],[L2]] -> 3826.5521 | BK17: =+IF(Tabla467824[[#This Row],[F]]=Tabla467824[[#This Row],[f2]], "IGUAL", "DISTINTO") -> IGUAL | BL17: =+IF(Tabla467824[[#This Row],[CVN]]=Tabla467824[[#This Row],[CVN2]], "IGUAL", "DISTINTO") -> DISTINTO | BM17: =+IF(Tabla467824[[#This Row],[L]]=Tabla467824[[#This Row],[L2]], "IGUAL", "DISTINTO") -> IGUAL
A18: 15 | B18: CAE500016 | C18: 3931LLT | D18: M1 | E18: GASOLINA | F18: GASOLINA | G18: M1 | H18: X | J18: X | L18: X | O18: AYVENS | P18: 1 | Q18: RENTING | R18: DEVUELTO | S18: 44224 | T18: 45685 | U18: 1461 | V18: 2025 | W18: 7 | X18: GASOLINA | Y18: SEAT | Z18: ARONA 1.0 TSI 115 CV | AA18: 1203 | AB18: E.Mixta Metropolitana, SA | AC18: 12039060 | AD18: 1 | AE18: 6082MWV | AF18: CITROEN | AG18: Ë-C3 ELÉCTRICO MAX | AH18: ELECTRICO | AI18: 12039060 | AJ18: 2024 | AK18: 45625 | AL18: -1 | AM18: 1203 | AN18: 4500424805 | AO18: E.Mixta Metropolitana, SA | AQ18: X | AR18: COMUNIDAD VALENCIANA | AS18: VR7CBZYA7RT153038 | AT18: 5.1 | AU18: 9.19 | AV18: 16.4 | AW18: 13073 | AX18: 3983.2124 | AY18: M1 | AZ18: CORRECTO ALQUILER | BA18: =+IF(Tabla467824[[#This Row],[TIPO VEHÍCULO]]=Tabla467824[[#This Row],[Columna2]], "IGUAL", "DISTINTO") -> IGUAL | BB18: =+IF(Tabla467824[[#This Row],[Columna4]]=Tabla467824[[#This Row],[Combustible2]], "IGUAL", "DISTINTO") -> IGUAL | BC18: CAE500016 | BD18: {=IFERROR(INDEX('[1]Anexos FICHA TRA050'!$D$27:$D$44, MATCH(Tabla467824[[#This Row],[Columna5]]&Tabla467824[[#This Row],[Columna4]], '[1]Anexos FICHA TRA050'!$E$27:$E$44&'[1]Anexos FICHA TRA050'!$F$27:$F$44, 0)), "")} -> 7.89 | BE18: =IFERROR(INDEX('[1]Anexos FICHA TRA050'!$B$4:$B$7, MATCH(Tabla467824[[#This Row],[Columna4]], '[1]Anexos FICHA TRA050'!$C$4:$C$7, 0)), "") -> 9.19 | BF18: =IFERROR(INDEX('[1]Anexos FICHA TRA050'!$C$14:$C$22, MATCH(Tabla467824[[#This Row],[Columna5]], '[1]Anexos FICHA TRA050'!$D$14:$D$22, 0)), "") -> 17.92 | BG18: =IFERROR(INDEX('[1]Anexos FICHA TRA050'!$C$49:$C$54, MATCH(Tabla467824[[#This Row],[Columna5]], '[1]Anexos FICHA TRA050'!$D$49:$D$54, 0)), "") -> 13073 | BH18: =+(((Tabla467824[[#This Row],[CVA2]]*Tabla467824[[#This Row],[f2]])-Tabla467824[[#This Row],[CVN2]])/100)*Tabla467824[[#This Row],[L2]] -> 7136.433 | BK18: =+IF(Tabla467824[[#This Row],[F]]=Tabla467824[[#This Row],[f2]], "IGUAL", "DISTINTO") -> IGUAL | BL18: =+IF(Tabla467824[[#This Row],[CVN]]=Tabla467824[[#This Row],[CVN2]], "IGUAL", "DISTINTO") -> DISTINTO | BM18: =+IF(Tabla467824[[#This Row],[L]]=Tabla467824[[#This Row],[L2]], "IGUAL", "DISTINTO") -> IGUAL
A19: 16 | B19: CAE500017 | C19: 5829LLX | D19: M1 | E19: GASOLINA | F19: GASOLINA | G19: M1 | H19: X | J19: X | L19: X | M19: X | O19: AYVENS | P19: 1 | Q19: RENTING | R19: DEVUELTO | S19: 44215 | T19: 45676 | U19: 1461 | V19: 2025 | W19: 7 | X19: GASOLINA | Y19: SEAT | Z19: ARONA 1.0 TSI 115 CV | AA19: 1001 | AB19: AVSA | AC19: 200590 | AD19: 3 | AE19: 9050MWN | AF19: CITROEN | AG19: Ë-C3 ELÉCTRICO MAX | AH19: ELECTRICO | AI19: 200541 | AJ19: 2024 | AK19: 45622 | AL19: -1 | AM19: 1001 | AN19: 4500424807 | AO19: AVSA | AQ19: X | AR19: COMUNIDAD VALENCIANA | AS19: VR7CBZYA1RT152189 | AT19: 5.1 | AU19: 9.19 | AV19: 16.4 | AW19: 13073 | AX19: 3983.2124 | AY19: M1 | AZ19: CORRECTO ALQUILER | BA19: =+IF(Tabla467824[[#This Row],[TIPO VEHÍCULO]]=Tabla467824[[#This Row],[Columna2]], "IGUAL", "DISTINTO") -> IGUAL | BB19: =+IF(Tabla467824[[#This Row],[Columna4]]=Tabla467824[[#This Row],[Combustible2]], "IGUAL", "DISTINTO") -> IGUAL | BC19: CAE500017 | BD19: {=IFERROR(INDEX('[1]Anexos FICHA TRA050'!$D$27:$D$44, MATCH(Tabla467824[[#This Row],[Columna5]]&Tabla467824[[#This Row],[Columna4]], '[1]Anexos FICHA TRA050'!$E$27:$E$44&'[1]Anexos FICHA TRA050'!$F$27:$F$44, 0)), "")} -> 7.89 | BE19: =IFERROR(INDEX('[1]Anexos FICHA TRA050'!$B$4:$B$7, MATCH(Tabla467824[[#This Row],[Columna4]], '[1]Anexos FICHA TRA050'!$C$4:$C$7, 0)), "") -> 9.19 | BF19: =IFERROR(INDEX('[1]Anexos FICHA TRA050'!$C$14:$C$22, MATCH(Tabla467824[[#This Row],[Columna5]], '[1]Anexos FICHA TRA050'!$D$14:$D$22, 0)), "") -> 17.92 | BG19: =IFERROR(INDEX('[1]Anexos FICHA TRA050'!$C$49:$C$54, MATCH(Tabla467824[[#This Row],[Columna5]], '[1]Anexos FICHA TRA050'!$D$49:$D$54, 0)), "") -> 13073 | BH19: =+(((Tabla467824[[#This Row],[CVA2]]*Tabla467824[[#This Row],[f2]])-Tabla467824[[#This Row],[CVN2]])/100)*Tabla467824[[#This Row],[L2]] -> 7136.433 | BK19: =+IF(Tabla467824[[#This Row],[F]]=Tabla467824[[#This Row],[f2]], "IGUAL", "DISTINTO") -> IGUAL | BL19: =+IF(Tabla467824[[#This Row],[CVN]]=Tabla467824[[#This Row],[CVN2]], "IGUAL", "DISTINTO") -> DISTINTO | BM19: =+IF(Tabla467824[[#This Row],[L]]=Tabla467824[[#This Row],[L2]], "IGUAL", "DISTINTO") -> IGUAL
A20: 17 | B20: CAE500018 | C20: 3904LLT | D20: M1 | E20: GASOLINA | F20: GASOLINA | G20: M1 | H20: X | J20: X | L20: X | M20: X | O20: AYVENS | P20: 1 | Q20: RENTING | R20: DEVUELTO | S20: 44224 | T20: 45689 | U20: 1465 | V20: 2025 | W20: 7 | X20: GASOLINA | Y20: SEAT | Z20: ARONA 1.0 TSI 115 CV | AA20: 1200 | AB20: EMIVASA | AC20: 12009060 | AD20: 2 | AE20: 3133MWZ | AF20: CITROEN | AG20: Ë-C3 ELÉCTRICO MAX | AH20: ELECTRICO | AI20: 200020 | AJ20: 2024 | AK20: 45638 | AL20: -1 | AM20: 1200 | AN20: 4500424896 | AO20: EMIVASA | AQ20: X | AR20: COMUNIDAD VALENCIANA | AS20: VR7CBZYA2RT154436 | AT20: 5.1 | AU20: 9.19 | AV20: 16.4 | AW20: 13073 | AX20: 3983.2124 | AY20: M1 | AZ20: CORRECTO ALQUILER | BA20: =+IF(Tabla467824[[#This Row],[TIPO VEHÍCULO]]=Tabla467824[[#This Row],[Columna2]], "IGUAL", "DISTINTO") -> IGUAL | BB20: =+IF(Tabla467824[[#This Row],[Columna4]]=Tabla467824[[#This Row],[Combustible2]], "IGUAL", "DISTINTO") -> IGUAL | BC20: CAE500018 | BD20: {=IFERROR(INDEX('[1]Anexos FICHA TRA050'!$D$27:$D$44, MATCH(Tabla467824[[#This Row],[Columna5]]&Tabla467824[[#This Row],[Columna4]], '[1]Anexos FICHA TRA050'!$E$27:$E$44&'[1]Anexos FICHA TRA050'!$F$27:$F$44, 0)), "")} -> 7.89 | BE20: =IFERROR(INDEX('[1]Anexos FICHA TRA050'!$B$4:$B$7, MATCH(Tabla467824[[#This Row],[Columna4]], '[1]Anexos FICHA TRA050'!$C$4:$C$7, 0)), "") -> 9.19 | BF20: =IFERROR(INDEX('[1]Anexos FICHA TRA050'!$C$14:$C$22, MATCH(Tabla467824[[#This Row],[Columna5]], '[1]Anexos FICHA TRA050'!$D$14:$D$22, 0)), "") -> 17.92 | BG20: =IFERROR(INDEX('[1]Anexos FICHA TRA050'!$C$49:$C$54, MATCH(Tabla467824[[#This Row],[Columna5]], '[1]Anexos FICHA TRA050'!$D$49:$D$54, 0)), "") -> 13073 | BH20: =+(((Tabla467824[[#This Row],[CVA2]]*Tabla467824[[#This Row],[f2]])-Tabla467824[[#This Row],[CVN2]])/100)*Tabla467824[[#This Row],[L2]] -> 7136.433 | BK20: =+IF(Tabla467824[[#This Row],[F]]=Tabla467824[[#This Row],[f2]], "IGUAL", "DISTINTO") -> IGUAL | BL20: =+IF(Tabla467824[[#This Row],[CVN]]=Tabla467824[[#This Row],[CVN2]], "IGUAL", "DISTINTO") -> DISTINTO | BM20: =+IF(Tabla467824[[#This Row],[L]]=Tabla467824[[#This Row],[L2]], "IGUAL", "DISTINTO") -> IGUAL
A21: 18 | B21: CAE500019 | C21: 9417LKC | D21: M1 | E21: DIESEL | F21: DIESEL | G21: M1 | H21: X | J21: X | L21: X | O21: AYVENS | P21: 1 | Q21: RENTING | R21: DEVUELTO | S21: 44133 | T21: 45594 | U21: 1461 | V21: 2024 | W21: 7 | X21: DIESEL | Y21: SEAT | Z21: ARONA 1.6 TDI 95 CV | AA21: 1200 | AB21: EMIVASA | AC21: 12009060 | AD21: 3 | AE21: 3105MWZ | AF21: CITROEN | AG21: Ë-C3 ELÉCTRICO MAX | AH21: ELECTRICO | AI21: 200020 | AJ21: 2024 | AK21: 45638 | AL21: 0 | AM21: 1200 | AN21: 4500424877 | AO21: EMIVASA | AQ21: X | AR21: COMUNIDAD VALENCIANA | AS21: VR7CBZYA3RT153022 | AT21: 5.1 | AU21: 10 | AV21: 16.4 | AW21: 13073 | AX21: 4523.258 | AY21: M1 | AZ21: CORRECTO ALQUILER | BA21: =+IF(Tabla467824[[#This Row],[TIPO VEHÍCULO]]=Tabla467824[[#This Row],[Columna2]], "IGUAL", "DISTINTO") -> IGUAL | BB21: =+IF(Tabla467824[[#This Row],[Columna4]]=Tabla467824[[#This Row],[Combustible2]], "IGUAL", "DISTINTO") -> IGUAL | BC21: CAE500019 | BD21: {=IFERROR(INDEX('[1]Anexos FICHA TRA050'!$D$27:$D$44, MATCH(Tabla467824[[#This Row],[Columna5]]&Tabla467824[[#This Row],[Columna4]], '[1]Anexos FICHA TRA050'!$E$27:$E$44&'[1]Anexos FICHA TRA050'!$F$27:$F$44, 0)), "")} -> 6.99 | BE21: =IFERROR(INDEX('[1]Anexos FICHA TRA050'!$B$4:$B$7, MATCH(Tabla467824[[#This Row],[Columna4]], '[1]Anexos FICHA TRA050'!$C$4:$C$7, 0)), "") -> 10 | BF21: =IFERROR(INDEX('[1]Anexos FICHA TRA050'!$C$14:$C$22, MATCH(Tabla467824[[#This Row],[Columna5]], '[1]Anexos FICHA TRA050'!$D$14:$D$22, 0)), "") -> 17.92 | BG21: =IFERROR(INDEX('[1]Anexos FICHA TRA050'!$C$49:$C$54, MATCH(Tabla467824[[#This Row],[Columna5]], '[1]Anexos FICHA TRA050'!$D$49:$D$54, 0)), "") -> 13073 | BH21: =+(((Tabla467824[[#This Row],[CVA2]]*Tabla467824[[#This Row],[f2]])-Tabla467824[[#This Row],[CVN2]])/100)*Tabla467824[[#This Row],[L2]] -> 6795.3454 | BK21: =+IF(Tabla467824[[#This Row],[F]]=Tabla467824[[#This Row],[f2]], "IGUAL", "DISTINTO") -> IGUAL | BL21: =+IF(Tabla467824[[#This Row],[CVN]]=Tabla467824[[#This Row],[CVN2]], "IGUAL", "DISTINTO") -> DISTINTO | BM21: =+IF(Tabla467824[[#This Row],[L]]=Tabla467824[[#This Row],[L2]], "IGUAL", "DISTINTO") -> IGUAL
A22: 19 | B22: CAE500020 | C22: 9418LKC | D22: M1 | E22: DIESEL | F22: DIESEL | G22: M1 | H22: X | J22: X | L22: X | M22: X | O22: AYVENS | P22: 1 | Q22: RENTING | R22: DEVUELTO | S22: 44133 | T22: 45594 | U22: 1461 | V22: 2024 | W22: 7 | X22: DIESEL | Y22: SEAT | Z22: ARONA 1.6 TDI 95 CV | AA22: 1001 | AB22: AVSA | AC22: 101702 | AD22: 4 | AE22: 6028MWV | AF22: CITROEN | AG22: Ë-C3 ELÉCTRICO MAX | AH22: ELECTRICO | AI22: 200590 | AJ22: 2024 | AK22: 45622 | AL22: 0 | AM22: 1001 | AN22: 4500424796 | AO22: AVSA | AQ22: X | AR22: COMUNIDAD VALENCIANA | AS22: VR7CBZYA2RT152184 | AT22: 5.1 | AU22: 10 | AV22: 16.4 | AW22: 13073 | AX22: 4523.258 | AY22: M1 | AZ22: CORRECTO ALQUILER | BA22: =+IF(Tabla467824[[#This Row],[TIPO VEHÍCULO]]=Tabla467824[[#This Row],[Columna2]], "IGUAL", "DISTINTO") -> IGUAL | BB22: =+IF(Tabla467824[[#This Row],[Columna4]]=Tabla467824[[#This Row],[Combustible2]], "IGUAL", "DISTINTO") -> IGUAL | BC22: CAE500020 | BD22: {=IFERROR(INDEX('[1]Anexos FICHA TRA050'!$D$27:$D$44, MATCH(Tabla467824[[#This Row],[Columna5]]&Tabla467824[[#This Row],[Columna4]], '[1]Anexos FICHA TRA050'!$E$27:$E$44&'[1]Anexos FICHA TRA050'!$F$27:$F$44, 0)), "")} -> 6.99 | BE22: =IFERROR(INDEX('[1]Anexos FICHA TRA050'!$B$4:$B$7, MATCH(Tabla467824[[#This Row],[Columna4]], '[1]Anexos FICHA TRA050'!$C$4:$C$7, 0)), "") -> 10 | BF22: =IFERROR(INDEX('[1]Anexos FICHA TRA050'!$C$14:$C$22, MATCH(Tabla467824[[#This Row],[Columna5]], '[1]Anexos FICHA TRA050'!$D$14:$D$22, 0)), "") -> 17.92 | BG22: =IFERROR(INDEX('[1]Anexos FICHA TRA050'!$C$49:$C$54, MATCH(Tabla467824[[#This Row],[Columna5]], '[1]Anexos FICHA TRA050'!$D$49:$D$54, 0)), "") -> 13073 | BH22: =+(((Tabla467824[[#This Row],[CVA2]]*Tabla467824[[#This Row],[f2]])-Tabla467824[[#This Row],[CVN2]])/100)*Tabla467824[[#This Row],[L2]] -> 6795.3454 | BK22: =+IF(Tabla467824[[#This Row],[F]]=Tabla467824[[#This Row],[f2]], "IGUAL", "DISTINTO") -> IGUAL | BL22: =+IF(Tabla467824[[#This Row],[CVN]]=Tabla467824[[#This Row],[CVN2]], "IGUAL", "DISTINTO") -> DISTINTO | BM22: =+IF(Tabla467824[[#This Row],[L]]=Tabla467824[[#This Row],[L2]], "IGUAL", "DISTINTO") -> IGUAL
A23: 20 | B23: CAE500030 | C23: 9428LKC | D23: M1 | E23: DIESEL | F23: DIESEL | G23: M1 | H23: X | L23: x | M23: x | O23: AYVENS | P23: 1 | Q23: RENTING | R23: CANCELADO POR SINIESTRO | S23: 44133 | T23: 45594 | U23: 1461 | V23: 2024 | W23: 6 | X23: DIESEL | Y23: SEAT | Z23: ARONA 1.6 TDI 95 CV | AA23: 1001 | AB23: AVSA | AC23: 200750 | AD23: 5 | AE23: 6029MWV | AF23: CITROEN | AG23: Ë-C3 ELÉCTRICO MAX | AH23: ELECTRICO | AI23: 200714 | AJ23: 2024 | AK23: 45625 | AL23: 0 | AM23: 1001 | AN23: 4500424793 | AO23: AVSA | AQ23: X | AR23: COMUNIDAD VALENCIANA | AS23: VR7CBZYA7RT152178 | AT23: 5.1 | AU23: 10 | AV23: 16.4 | AW23: 13073 | AX23: 4523.258 | AY23: M1 | AZ23: FALSO ALQUILER | BA23: =+IF(Tabla467824[[#This Row],[TIPO VEHÍCULO]]=Tabla467824[[#This Row],[Columna2]], "IGUAL", "DISTINTO") -> IGUAL | BB23: =+IF(Tabla467824[[#This Row],[Columna4]]=Tabla467824[[#This Row],[Combustible2]], "IGUAL", "DISTINTO") -> IGUAL | BC23: CAE500030 | BD23: {=IFERROR(INDEX('[1]Anexos FICHA TRA050'!$D$27:$D$44, MATCH(Tabla467824[[#This Row],[Columna5]]&Tabla467824[[#This Row],[Columna4]], '[1]Anexos FICHA TRA050'!$E$27:$E$44&'[1]Anexos FICHA TRA050'!$F$27:$F$44, 0)), "")} -> 6.99 | BE23: =IFERROR(INDEX('[1]Anexos FICHA TRA050'!$B$4:$B$7, MATCH(Tabla467824[[#This Row],[Columna4]], '[1]Anexos FICHA TRA050'!$C$4:$C$7, 0)), "") -> 10 | BF23: =IFERROR(INDEX('[1]Anexos FICHA TRA050'!$C$14:$C$22, MATCH(Tabla467824[[#This Row],[Columna5]], '[1]Anexos FICHA TRA050'!$D$14:$D$22, 0)), "") -> 17.92 | BG23: =IFERROR(INDEX('[1]Anexos FICHA TRA050'!$C$49:$C$54, MATCH(Tabla467824[[#This Row],[Columna5]], '[1]Anexos FICHA TRA050'!$D$49:$D$54, 0)), "") -> 13073 | BH23: =+(((Tabla467824[[#This Row],[CVA2]]*Tabla467824[[#This Row],[f2]])-Tabla467824[[#This Row],[CVN2]])/100)*Tabla467824[[#This Row],[L2]] -> 6795.3454 | BK23: =+IF(Tabla467824[[#This Row],[F]]=Tabla467824[[#This Row],[f2]], "IGUAL", "DISTINTO") -> IGUAL | BL23: =+IF(Tabla467824[[#This Row],[CVN]]=Tabla467824[[#This Row],[CVN2]], "IGUAL", "DISTINTO") -> DISTINTO | BM23: =+IF(Tabla467824[[#This Row],[L]]=Tabla467824[[#This Row],[L2]], "IGUAL", "DISTINTO") -> IGUAL
A24: 21 | B24: CAE500044 | C24: 9431LKC | D24: M1 | E24: DIESEL | F24: DIESEL | G24: M1 | H24: X | J24: X | L24: X | M24: X | O24: AYVENS | P24: 1 | Q24: RENTING | R24: DEVUELTO | S24: 44133 | T24: 45594 | U24: 1461 | V24: 2024 | W24: 7 | X24: DIESEL | Y24: SEAT | Z24: ARONA 1.6 TDI 95 CV | AA24: 1001 | AB24: AVSA | AC24: 200300 | AD24: 6 | AE24: 6042MWV | AF24: CITROEN | AG24: Ë-C3 ELÉCTRICO MAX | AH24: ELECTRICO | AI24: 201510 | AJ24: 2024 | AK24: 45625 | AL24: 0 | AM24: 1001 | AN24: 4500424791 | AO24: AVSA | AQ24: X | AR24: COMUNIDAD VALENCIANA | AS24: VR7CBZYA0RT152183 | AT24: 5.1 | AU24: 10 | AV24: 16.4 | AW24: 13073 | AX24: 4523.258 | AY24: M1 | AZ24: CORRECTO ALQUILER | BA24: =+IF(Tabla467824[[#This Row],[TIPO VEHÍCULO]]=Tabla467824[[#This Row],[Columna2]], "IGUAL", "DISTINTO") -> IGUAL | BB24: =+IF(Tabla467824[[#This Row],[Columna4]]=Tabla467824[[#This Row],[Combustible2]], "IGUAL", "DISTINTO") -> IGUAL | BC24: CAE500044 | BD24: {=IFERROR(INDEX('[1]Anexos FICHA TRA050'!$D$27:$D$44, MATCH(Tabla467824[[#This Row],[Columna5]]&Tabla467824[[#This Row],[Columna4]], '[1]Anexos FICHA TRA050'!$E$27:$E$44&'[1]Anexos FICHA TRA050'!$F$27:$F$44, 0)), "")} -> 6.99 | BE24: =IFERROR(INDEX('[1]Anexos FICHA TRA050'!$B$4:$B$7, MATCH(Tabla467824[[#This Row],[Columna4]], '[1]Anexos FICHA TRA050'!$C$4:$C$7, 0)), "") -> 10 | BF24: =IFERROR(INDEX('[1]Anexos FICHA TRA050'!$C$14:$C$22, MATCH(Tabla467824[[#This Row],[Columna5]], '[1]Anexos FICHA TRA050'!$D$14:$D$22, 0)), "") -> 17.92 | BG24: =IFERROR(INDEX('[1]Anexos FICHA TRA050'!$C$49:$C$54, MATCH(Tabla467824[[#This Row],[Columna5]], '[1]Anexos FICHA TRA050'!$D$49:$D$54, 0)), "") -> 13073 | BH24: =+(((Tabla467824[[#This Row],[CVA2]]*Tabla467824[[#This Row],[f2]])-Tabla467824[[#This Row],[CVN2]])/100)*Tabla467824[[#This Row],[L2]] -> 6795.3454 | BK24: =+IF(Tabla467824[[#This Row],[F]]=Tabla467824[[#This Row],[f2]], "IGUAL", "DISTINTO") -> IGUAL | BL24: =+IF(Tabla467824[[#This Row],[CVN]]=Tabla467824[[#This Row],[CVN2]], "IGUAL", "DISTINTO") -> DISTINTO | BM24: =+IF(Tabla467824[[#This Row],[L]]=Tabla467824[[#This Row],[L2]], "IGUAL", "DISTINTO") -> IGUAL
A25: 22 | B25: CAE500045 | C25: 9494LKC | D25: M1 | E25: DIESEL | F25: DIESEL | G25: M1 | H25: X | J25: X | L25: X | M25: X | O25: AYVENS | P25: 1 | Q25: RENTING | R25: DEVUELTO | S25: 44133 | T25: 45594 | U25: 1461 | V25: 2024 | W25: 7 | X25: DIESEL | Y25: SEAT | Z25: ARONA 1.6 TDI 95 CV | AA25: 1001 | AB25: AVSA | AC25: 200542 | AD25: 7 | AE25: 6046MWV | AF25: CITROEN | AG25: Ë-C3 ELÉCTRICO MAX | AH25: ELECTRICO | AI25: 200560 | AJ25: 2024 | AK25: 45625 | AL25: 0 | AM25: 1001 | AN25: 4500424792 | AO25: AVSA | AQ25: X | AR25: COMUNIDAD VALENCIANA | AS25: VR7CBZYA9RT152182 | AT25: 5.1 | AU25: 10 | AV25: 16.4 | AW25: 13073 | AX25: 4523.258 | AY25: M1 | AZ25: CORRECTO ALQUILER | BA25: =+IF(Tabla467824[[#This Row],[TIPO VEHÍCULO]]=Tabla467824[[#This Row],[Columna2]], "IGUAL", "DISTINTO") -> IGUAL | BB25: =+IF(Tabla467824[[#This Row],[Columna4]]=Tabla467824[[#This Row],[Combustible2]], "IGUAL", "DISTINTO") -> IGUAL | BC25: CAE500045 | BD25: {=IFERROR(INDEX('[1]Anexos FICHA TRA050'!$D$27:$D$44, MATCH(Tabla467824[[#This Row],[Columna5]]&Tabla467824[[#This Row],[Columna4]], '[1]Anexos FICHA TRA050'!$E$27:$E$44&'[1]Anexos FICHA TRA050'!$F$27:$F$44, 0)), "")} -> 6.99 | BE25: =IFERROR(INDEX('[1]Anexos FICHA TRA050'!$B$4:$B$7, MATCH(Tabla467824[[#This Row],[Columna4]], '[1]Anexos FICHA TRA050'!$C$4:$C$7, 0)), "") -> 10 | BF25: =IFERROR(INDEX('[1]Anexos FICHA TRA050'!$C$14:$C$22, MATCH(Tabla467824[[#This Row],[Columna5]], '[1]Anexos FICHA TRA050'!$D$14:$D$22, 0)), "") -> 17.92 | BG25: =IFERROR(INDEX('[1]Anexos FICHA TRA050'!$C$49:$C$54, MATCH(Tabla467824[[#This Row],[Columna5]], '[1]Anexos FICHA TRA050'!$D$49:$D$54, 0)), "") -> 13073 | BH25: =+(((Tabla467824[[#This Row],[CVA2]]*Tabla467824[[#This Row],[f2]])-Tabla467824[[#This Row],[CVN2]])/100)*Tabla467824[[#This Row],[L2]] -> 6795.3454 | BK25: =+IF(Tabla467824[[#This Row],[F]]=Tabla467824[[#This Row],[f2]], "IGUAL", "DISTINTO") -> IGUAL | BL25: =+IF(Tabla467824[[#This Row],[CVN]]=Tabla467824[[#This Row],[CVN2]], "IGUAL", "DISTINTO") -> DISTINTO | BM25: =+IF(Tabla467824[[#This Row],[L]]=Tabla467824[[#This Row],[L2]], "IGUAL", "DISTINTO") -> IGUAL
A26: 23 | B26: CAE500046 | C26: 0818LKK | D26: M1 | E26: DIESEL | F26: DIESEL | G26: M1 | H26: X | J26: X | L26: X | M26: X | O26: AYVENS | P26: 1 | Q26: RENTING | R26: DEVUELTO | S26: 44134 | T26: 45595 | U26: 1461 | V26: 2024 | W26: 7 | X26: DIESEL | Y26: SEAT | Z26: ARONA 1.6 TDI 95 CV | AA26: 1021 | AB26: MEDICION AVANZADA CONTAD. | AC26: 357108 | AD26: 8 | AE26: 6492MWV | AF26: CITROEN | AG26: Ë-C3 ELÉCTRICO MAX | AH26: ELECTRICO | AI26: 357108 | AJ26: 2024 | AK26: 45625 | AL26: 0 | AM26: 1021 | AN26: 4500424794 | AO26: MEDICION AVANZADA CONTAD. | AQ26: X | AR26: COMUNIDAD VALENCIANA | AS26: VR7CBZYA5RT154429 | AT26: 5.1 | AU26: 10 | AV26: 16.4 | AW26: 13073 | AX26: 4523.258 | AY26: M1 | AZ26: CORRECTO ALQUILER | BA26: =+IF(Tabla467824[[#This Row],[TIPO VEHÍCULO]]=Tabla467824[[#This Row],[Columna2]], "IGUAL", "DISTINTO") -> IGUAL | BB26: =+IF(Tabla467824[[#This Row],[Columna4]]=Tabla467824[[#This Row],[Combustible2]], "IGUAL", "DISTINTO") -> IGUAL | BC26: CAE500046 | BD26: {=IFERROR(INDEX('[1]Anexos FICHA TRA050'!$D$27:$D$44, MATCH(Tabla467824[[#This Row],[Columna5]]&Tabla467824[[#This Row],[Columna4]], '[1]Anexos FICHA TRA050'!$E$27:$E$44&'[1]Anexos FICHA TRA050'!$F$27:$F$44, 0)), "")} -> 6.99 | BE26: =IFERROR(INDEX('[1]Anexos FICHA TRA050'!$B$4:$B$7, MATCH(Tabla467824[[#This Row],[Columna4]], '[1]Anexos FICHA TRA050'!$C$4:$C$7, 0)), "") -> 10 | BF26: =IFERROR(INDEX('[1]Anexos FICHA TRA050'!$C$14:$C$22, MATCH(Tabla467824[[#This Row],[Columna5]], '[1]Anexos FICHA TRA050'!$D$14:$D$22, 0)), "") -> 17.92 | BG26: =IFERROR(INDEX('[1]Anexos FICHA TRA050'!$C$49:$C$54, MATCH(Tabla467824[[#This Row],[Columna5]], '[1]Anexos FICHA TRA050'!$D$49:$D$54, 0)), "") -> 13073 | BH26: =+(((Tabla467824[[#This Row],[CVA2]]*Tabla467824[[#This Row],[f2]])-Tabla467824[[#This Row],[CVN2]])/100)*Tabla467824[[#This Row],[L2]] -> 6795.3454 | BK26: =+IF(Tabla467824[[#This Row],[F]]=Tabla467824[[#This Row],[f2]], "IGUAL", "DISTINTO") -> IGUAL | BL26: =+IF(Tabla467824[[#This Row],[CVN]]=Tabla467824[[#This Row],[CVN2]], "IGUAL", "DISTINTO") -> DISTINTO | BM26: =+IF(Tabla467824[[#This Row],[L]]=Tabla467824[[#This Row],[L2]], "IGUAL", "DISTINTO") -> IGUAL
A27: 24 | B27: CAE500047 | C27: 4170LKY | D27: M1 | E27: DIESEL | F27: DIESEL | G27: M1 | H27: X | J27: X | L27: X | M27: X | O27: AYVENS | P27: 1 | Q27: RENTING | R27: DEVUELTO | S27: 44166 | T27: 45627 | U27: 1461 | V27: 2024 | W27: 7 | X27: DIESEL | Y27: SEAT | Z27: ARONA 1.6 TDI 95 CV | AA27: 1200 | AB27: EMIVASA | AC27: 12009060 | AD27: 4 | AE27: 3121MWZ | AF27: CITROEN | AG27: Ë-C3 ELÉCTRICO MAX | AH27: ELECTRICO | AI27: 100041 | AJ27: 2024 | AK27: 45638 | AL27: 0 | AM27: 1200 | AN27: 4500424898 | AO27: EMIVASA | AQ27: X | AR27: COMUNIDAD VALENCIANA | AS27: VR7CBZYA1RT153035 | AT27: 5.1 | AU27: 10 | AV27: 16.4 | AW27: 13073 | AX27: 4523.258 | AY27: M1 | AZ27: CORRECTO ALQUILER | BA27: =+IF(Tabla467824[[#This Row],[TIPO VEHÍCULO]]=Tabla467824[[#This Row],[Columna2]], "IGUAL", "DISTINTO") -> IGUAL | BB27: =+IF(Tabla467824[[#This Row],[Columna4]]=Tabla467824[[#This Row],[Combustible2]], "IGUAL", "DISTINTO") -> IGUAL | BC27: CAE500047 | BD27: {=IFERROR(INDEX('[1]Anexos FICHA TRA050'!$D$27:$D$44, MATCH(Tabla467824[[#This Row],[Columna5]]&Tabla467824[[#This Row],[Columna4]], '[1]Anexos FICHA TRA050'!$E$27:$E$44&'[1]Anexos FICHA TRA050'!$F$27:$F$44, 0)), "")} -> 6.99 | BE27: =IFERROR(INDEX('[1]Anexos FICHA TRA050'!$B$4:$B$7, MATCH(Tabla467824[[#This Row],[Columna4]], '[1]Anexos FICHA TRA050'!$C$4:$C$7, 0)), "") -> 10 | BF27: =IFERROR(INDEX('[1]Anexos FICHA TRA050'!$C$14:$C$22, MATCH(Tabla467824[[#This Row],[Columna5]], '[1]Anexos FICHA TRA050'!$D$14:$D$22, 0)), "") -> 17.92 | BG27: =IFERROR(INDEX('[1]Anexos FICHA TRA050'!$C$49:$C$54, MATCH(Tabla467824[[#This Row],[Columna5]], '[1]Anexos FICHA TRA050'!$D$49:$D$54, 0)), "") -> 13073 | BH27: =+(((Tabla467824[[#This Row],[CVA2]]*Tabla467824[[#This Row],[f2]])-Tabla467824[[#This Row],[CVN2]])/100)*Tabla467824[[#This Row],[L2]] -> 6795.3454 | BK27: =+IF(Tabla467824[[#This Row],[F]]=Tabla467824[[#This Row],[f2]], "IGUAL", "DISTINTO") -> IGUAL | BL27: =+IF(Tabla467824[[#This Row],[CVN]]=Tabla467824[[#This Row],[CVN2]], "IGUAL", "DISTINTO") -> DISTINTO | BM27: =+IF(Tabla467824[[#This Row],[L]]=Tabla467824[[#This Row],[L2]], "IGUAL", "DISTINTO") -> IGUAL
A28: 25 | B28: CAE500050 | C28: 8030LKY | D28: M1 | E28: DIESEL | F28: DIESEL | G28: M1 | H28: X | J28: X | L28: X | M28: X | O28: AYVENS | P28: 1 | Q28: RENTING | R28: DEVUELTO | S28: 44166 | T28: 45627 | U28: 1461 | V28: 2024 | W28: 7 | X28: DIESEL | Y28: SEAT | Z28: ARONA 1.6 TDI 95 CV | AA28: 1021 | AB28: MEDICION AVANZADA CONTAD. | AC28: 357107 | AD28: 9 | AE28: 6493MWV | AF28: CITROEN | AG28: Ë-C3 ELÉCTRICO MAX | AH28: ELECTRICO | AI28: 357107 | AJ28: 2024 | AK28: 45625 | AL28: 0 | AM28: 1021 | AN28: 4500424809 | AO28: MEDICION AVANZADA CONTAD. | AQ28: X | AR28: COMUNIDAD VALENCIANA | AS28: VR7CBZYA2RT152198 | AT28: 5.1 | AU28: 10 | AV28: 16.4 | AW28: 13073 | AX28: 4523.258 | AY28: M1 | AZ28: CORRECTO ALQUILER | BA28: =+IF(Tabla467824[[#This Row],[TIPO VEHÍCULO]]=Tabla467824[[#This Row],[Columna2]], "IGUAL", "DISTINTO") -> IGUAL | BB28: =+IF(Tabla467824[[#This Row],[Columna4]]=Tabla467824[[#This Row],[Combustible2]], "IGUAL", "DISTINTO") -> IGUAL | BC28: CAE500050 | BD28: {=IFERROR(INDEX('[1]Anexos FICHA TRA050'!$D$27:$D$44, MATCH(Tabla467824[[#This Row],[Columna5]]&Tabla467824[[#This Row],[Columna4]], '[1]Anexos FICHA TRA050'!$E$27:$E$44&'[1]Anexos FICHA TRA050'!$F$27:$F$44, 0)), "")} -> 6.99 | BE28: =IFERROR(INDEX('[1]Anexos FICHA TRA050'!$B$4:$B$7, MATCH(Tabla467824[[#This Row],[Columna4]], '[1]Anexos FICHA TRA050'!$C$4:$C$7, 0)), "") -> 10 | BF28: =IFERROR(INDEX('[1]Anexos FICHA TRA050'!$C$14:$C$22, MATCH(Tabla467824[[#This Row],[Columna5]], '[1]Anexos FICHA TRA050'!$D$14:$D$22, 0)), "") -> 17.92 | BG28: =IFERROR(INDEX('[1]Anexos FICHA TRA050'!$C$49:$C$54, MATCH(Tabla467824[[#This Row],[Columna5]], '[1]Anexos FICHA TRA050'!$D$49:$D$54, 0)), "") -> 13073 | BH28: =+(((Tabla467824[[#This Row],[CVA2]]*Tabla467824[[#This Row],[f2]])-Tabla467824[[#This Row],[CVN2]])/100)*Tabla467824[[#This Row],[L2]] -> 6795.3454 | BK28: =+IF(Tabla467824[[#This Row],[F]]=Tabla467824[[#This Row],[f2]], "IGUAL", "DISTINTO") -> IGUAL | BL28: =+IF(Tabla467824[[#This Row],[CVN]]=Tabla467824[[#This Row],[CVN2]], "IGUAL", "DISTINTO") -> DISTINTO | BM28: =+IF(Tabla467824[[#This Row],[L]]=Tabla467824[[#This Row],[L2]], "IGUAL", "DISTINTO") -> IGUAL
A29: 26 | B29: CAE500051 | C29: 8066LKY | D29: M1 | E29: DIESEL | F29: DIESEL | G29: M1 | H29: X | J29: X | L29: X | M29: X | O29: AYVENS | P29: 1 | Q29: RENTING | R29: DEVUELTO | S29: 44166 | T29: 45627 | U29: 1461 | V29: 2024 | W29: 7 | X29: DIESEL | Y29: SEAT | Z29: ARONA 1.6 TDI 95 CV | AA29: 1200 | AB29: EMIVASA | AC29: 12009060 | AD29: 5 | AE29: 3122MWZ | AF29: CITROEN | AG29: Ë-C3 ELÉCTRICO MAX | AH29: ELECTRICO | AI29: 200028 | AJ29: 2024 | AK29: 45638 | AL29: 0 | AM29: 1200 | AN29: 4500424889 | AO29: EMIVASA | AQ29: X | AR29: COMUNIDAD VALENCIANA | AS29: VR7CBZYA7RT154433 | AT29: 5.1 | AU29: 10 | AV29: 16.4 | AW29: 13073 | AX29: 4523.258 | AY29: M1 | AZ29: CORRECTO ALQUILER | BA29: =+IF(Tabla467824[[#This Row],[TIPO VEHÍCULO]]=Tabla467824[[#This Row],[Columna2]], "IGUAL", "DISTINTO") -> IGUAL | BB29: =+IF(Tabla467824[[#This Row],[Columna4]]=Tabla467824[[#This Row],[Combustible2]], "IGUAL", "DISTINTO") -> IGUAL | BC29: CAE500051 | BD29: {=IFERROR(INDEX('[1]Anexos FICHA TRA050'!$D$27:$D$44, MATCH(Tabla467824[[#This Row],[Columna5]]&Tabla467824[[#This Row],[Columna4]], '[1]Anexos FICHA TRA050'!$E$27:$E$44&'[1]Anexos FICHA TRA050'!$F$27:$F$44, 0)), "")} -> 6.99 | BE29: =IFERROR(INDEX('[1]Anexos FICHA TRA050'!$B$4:$B$7, MATCH(Tabla467824[[#This Row],[Columna4]], '[1]Anexos FICHA TRA050'!$C$4:$C$7, 0)), "") -> 10 | BF29: =IFERROR(INDEX('[1]Anexos FICHA TRA050'!$C$14:$C$22, MATCH(Tabla467824[[#This Row],[Columna5]], '[1]Anexos FICHA TRA050'!$D$14:$D$22, 0)), "") -> 17.92 | BG29: =IFERROR(INDEX('[1]Anexos FICHA TRA050'!$C$49:$C$54, MATCH(Tabla467824[[#This Row],[Columna5]], '[1]Anexos FICHA TRA050'!$D$49:$D$54, 0)), "") -> 13073 | BH29: =+(((Tabla467824[[#This Row],[CVA2]]*Tabla467824[[#This Row],[f2]])-Tabla467824[[#This Row],[CVN2]])/100)*Tabla467824[[#This Row],[L2]] -> 6795.3454 | BK29: =+IF(Tabla467824[[#This Row],[F]]=Tabla467824[[#This Row],[f2]], "IGUAL", "DISTINTO") -> IGUAL | BL29: =+IF(Tabla467824[[#This Row],[CVN]]=Tabla467824[[#This Row],[CVN2]], "IGUAL", "DISTINTO") -> DISTINTO | BM29: =+IF(Tabla467824[[#This Row],[L]]=Tabla467824[[#This Row],[L2]], "IGUAL", "DISTINTO") -> IGUAL
A30: 27 | B30: CAE500054 | C30: 0269LLK | D30: M1 | E30: DIESEL | F30: DIESEL | G30: M1 | H30: X | J30: X | L30: X | M30: X | O30: AYVENS | P30: 1 | Q30: RENTING | R30: DEVUELTO | S30: 44179 | T30: 45640 | U30: 1461 | V30: 2024 | W30: 7 | X30: DIESEL | Y30: SEAT | Z30: ARONA 1.6 TDI 95 CV | AA30: 1001 | AB30: AVSA | AC30: 201701 | AD30: 8 | AE30: 6094MWV | AF30: CITROEN | AG30: Ë-C3 ELÉCTRICO MAX | AH30: ELECTRICO | AI30: 200317 | AJ30: 2024 | AK30: 45625 | AL30: 0 | AM30: 1001 | AN30: 4500426700 | AO30: AVSA | AQ30: X | AR30: COMUNIDAD VALENCIANA | AS30: VR7CBZYA4ST000168 | AT30: 5.1 | AU30: 10 | AV30: 16.4 | AW30: 13073 | AX30: 4523.258 | AY30: M1 | AZ30: CORRECTO ALQUILER | BA30: =+IF(Tabla467824[[#This Row],[TIPO VEHÍCULO]]=Tabla467824[[#This Row],[Columna2]], "IGUAL", "DISTINTO") -> IGUAL | BB30: =+IF(Tabla467824[[#This Row],[Columna4]]=Tabla467824[[#This Row],[Combustible2]], "IGUAL", "DISTINTO") -> IGUAL | BC30: CAE500054 | BD30: {=IFERROR(INDEX('[1]Anexos FICHA TRA050'!$D$27:$D$44, MATCH(Tabla467824[[#This Row],[Columna5]]&Tabla467824[[#This Row],[Columna4]], '[1]Anexos FICHA TRA050'!$E$27:$E$44&'[1]Anexos FICHA TRA050'!$F$27:$F$44, 0)), "")} -> 6.99 | BE30: =IFERROR(INDEX('[1]Anexos FICHA TRA050'!$B$4:$B$7, MATCH(Tabla467824[[#This Row],[Columna4]], '[1]Anexos FICHA TRA050'!$C$4:$C$7, 0)), "") -> 10 | BF30: =IFERROR(INDEX('[1]Anexos FICHA TRA050'!$C$14:$C$22, MATCH(Tabla467824[[#This Row],[Columna5]], '[1]Anexos FICHA TRA050'!$D$14:$D$22, 0)), "") -> 17.92 | BG30: =IFERROR(INDEX('[1]Anexos FICHA TRA050'!$C$49:$C$54, MATCH(Tabla467824[[#This Row],[Columna5]], '[1]Anexos FICHA TRA050'!$D$49:$D$54, 0)), "") -> 13073 | BH30: =+(((Tabla467824[[#This Row],[CVA2]]*Tabla467824[[#This Row],[f2]])-Tabla467824[[#This Row],[CVN2]])/100)*Tabla467824[[#This Row],[L2]] -> 6795.3454 | BK30: =+IF(Tabla467824[[#This Row],[F]]=Tabla467824[[#This Row],[f2]], "IGUAL", "DISTINTO") -> IGUAL | BL30: =+IF(Tabla467824[[#This Row],[CVN]]=Tabla467824[[#This Row],[CVN2]], "IGUAL", "DISTINTO") -> DISTINTO | BM30: =+IF(Tabla467824[[#This Row],[L]]=Tabla467824[[#This Row],[L2]], "IGUAL", "DISTINTO") -> IGUAL
